Workbook

Sheet Dashboard
A1: INVENTORY & SUPPLY CHAIN ANALYSIS
A3: TOTAL INVENTORY VALUE | B3: TOTAL STOCK QUANTITY | C3: TOTAL REVENUE | D3: STOCKOUT RECORDS | E3: LOST SALES UNITS | F3: AVERAGE LEAD TIME (DAYS) | H3: Stockout Status | I3: Number of Records
A4: =SUM(items_and_stock!O2:O3601) -> 38110323 | B4: =SUM(items_and_stock!N2:N3601) -> 1832833 | C4: =SUM(items_and_stock!U2:U3601) -> 23766768 | D4: =COUNTIF(items_and_stock!W2:W3601,"Y") -> 114 | E4: =SUM(items_and_stock!V2:V3601) -> 15934 | F4: =AVERAGE(items_and_stock!L2:L3601) -> 37.138155 | H4: Y | I4: =COUNTIF(items_and_stock!$W:$W,"Y") -> 114
H5: N | I5: =COUNTIF(items_and_stock!$W:$W,"N") -> 3486

Sheet items_and_stock
A1: Item code | B1: Description | C1: Category | D1: Supplier | E1: Warehouse | F1: Period | G1: Unit cost | H1: Landed cost (with freight) | I1: Average cost (stock value / qty) | J1: Selling price | K1: Lead time planned days | L1: Lead time actual days | M1: Qty received | N1: Qty on hand | O1: Stock value | P1: Qty allocated to orders | Q1: Qty available | R1: Weeks of cover | S1: Days since last sale (month end) | T1: Units sold | U1: Revenue | V1: Lost sales units (stockout) | W1: Stocked out (Y/N) | X1: Availability Check
A2: IT-10001 | B2: Ball bearing 20-1 | C2: Bearings | D2: Clearwater Supply | E2: Main warehouse | F2: 2024-09 | G2: 1.1 | H2: 1.1 | I2: 1.084438 | J2: 1.45 | K2: 25 | L2: 24 | M2: 168 | N2: 489 | O2: 530.29 | P2: 13 | Q2: 476 | R2: 14.09 | S2: 2 | T2: 204 | U2: 295.8 | V2: 0 | W2: N | X2: =IF(Table2[[#This Row],[Qty available]]>Table2[[#This Row],[Qty on hand]],"Check","OK") -> OK
A3: IT-10001 | B3: Ball bearing 20-1 | C3: Bearings | D3: Clearwater Supply | E3: Main warehouse | F3: 2024-10 | G3: 1.07 | H3: 1.07 | I3: 1.082943 | J3: 1.45 | K3: 25 | L3: 24 | M3: 56 | N3: 384 | O3: 415.85 | P3: 57 | Q3: 327 | R3: 9.72 | S3: 1 | T3: 161 | U3: 233.45 | V3: 0 | W3: N | X3: =IF(Table2[[#This Row],[Qty available]]>Table2[[#This Row],[Qty on hand]],"Check","OK") -> OK
A4: IT-10001 | B4: Ball bearing 20-1 | C4: Bearings | D4: Clearwater Supply | E4: Main warehouse | F4: 2024-11 | G4: 1.07 | H4: 1.07 | I4: 1.076872 | J4: 1.45 | K4: 25 | L4: 23 | M4: 340 | N4: 438 | O4: 471.67 | P4: 51 | Q4: 387 | R4: 8.75 | S4: 1 | T4: 286 | U4: 414.7 | V4: 0 | W4: N | X4: =IF(Table2[[#This Row],[Qty available]]>Table2[[#This Row],[Qty on hand]],"Check","OK") -> OK
A5: IT-10001 | B5: Ball bearing 20-1 | C5: Bearings | D5: Clearwater Supply | E5: Main warehouse | F5: 2024-12 | G5: 1.09 | H5: 1.09 | I5: 1.082397 | J5: 1.45 | K5: 25 | L5: 23 | M5: 318 | N5: 655 | O5: 708.97 | P5: 57 | Q5: 598 | R5: 15.71 | S5: 0 | T5: 101 | U5: 146.45 | V5: 0 | W5: N | X5: =IF(Table2[[#This Row],[Qty available]]>Table2[[#This Row],[Qty on hand]],"Check","OK") -> OK
A6: IT-10001 | B6: Ball bearing 20-1 | C6: Bearings | D6: Clearwater Supply | E6: Main warehouse | F6: 2025-01 | G6: 1.07 | H6: 1.07 | I6: 1.081253 | J6: 1.45 | K6: 25 | L6: 23 | M6: 67 | N6: 471 | O6: 509.27 | P6: 13 | Q6: 458 | R6: 9.7 | S6: 0 | T6: 251 | U6: 363.95 | V6: 0 | W6: N | X6: =IF(Table2[[#This Row],[Qty available]]>Table2[[#This Row],[Qty on hand]],"Check","OK") -> OK
A7: IT-10001 | B7: Ball bearing 20-1 | C7: Bearings | D7: Clearwater Supply | E7: Main warehouse | F7: 2025-02 | G7: 1.09 | H7: 1.09 | I7: 1.081596 | J7: 1.49 | K7: 25 | L7: 22 | M7: 19 | N7: 307 | O7: 332.05 | P7: 64 | Q7: 243 | R7: 7.38 | S7: 0 | T7: 183 | U7: 272.67 | V7: 0 | W7: N | X7: =IF(Table2[[#This Row],[Qty available]]>Table2[[#This Row],[Qty on hand]],"Check","OK") -> OK
A8: IT-10001 | B8: Ball bearing 20-1 | C8: Bearings | D8: Clearwater Supply | E8: Main warehouse | F8: 2025-03 | G8: 1.09 | H8: 1.09 | I8: 1.087405 | J8: 1.49 | K8: 25 | L8: 25 | M8: 689 | N8: 790 | O8: 859.05 | P8: 25 | Q8: 765 | R8: 15.87 | S8: 3 | T8: 206 | U8: 306.94 | V8: 0 | W8: N | X8: =IF(Table2[[#This Row],[Qty available]]>Table2[[#This Row],[Qty on hand]],"Check","OK") -> OK
A9: IT-10001 | B9: Ball bearing 20-1 | C9: Bearings | D9: Clearwater Supply | E9: Main warehouse | F9: 2025-04 | G9: 1.12 | H9: 1.12 | I9: 1.091548 | J9: 1.49 | K9: 25 | L9: 25 | M9: 115 | N9: 691 | O9: 754.26 | P9: 19 | Q9: 672 | R9: 14.57 | S9: 3 | T9: 214 | U9: 318.86 | V9: 0 | W9: N | X9: =IF(Table2[[#This Row],[Qty available]]>Table2[[#This Row],[Qty on hand]],"Check","OK") -> OK
A10: IT-10001 | B10: Ball bearing 20-1 | C10: Bearings | D10: Clearwater Supply | E10: Main warehouse | F10: 2025-05 | G10: 1.11 | H10: 1.11 | I10: 1.092201 | J10: 1.49 | K10: 25 | L10: 22 | M10: 25 | N10: 427 | O10: 466.37 | P10: 44 | Q10: 383 | R10: 7.92 | S10: 0 | T10: 289 | U10: 430.61 | V10: 0 | W10: N | X10: =IF(Table2[[#This Row],[Qty available]]>Table2[[#This Row],[Qty on hand]],"Check","OK") -> OK
A11: IT-10001 | B11: Ball bearing 20-1 | C11: Bearings | D11: Clearwater Supply | E11: Main warehouse | F11: 2025-06 | G11: 1.12 | H11: 1.12 | I11: 1.096409 | J11: 1.49 | K11: 25 | L11: 23 | M11: 76 | N11: 337 | O11: 369.49 | P11: 19 | Q11: 318 | R11: 6.55 | S11: 1 | T11: 166 | U11: 247.34 | V11: 0 | W11: N | X11: =IF(Table2[[#This Row],[Qty available]]>Table2[[#This Row],[Qty on hand]],"Check","OK") -> OK
A12: IT-10001 | B12: Ball bearing 20-1 | C12: Bearings | D12: Clearwater Supply | E12: Main warehouse | F12: 2025-07 | G12: 1.09 | H12: 1.09 | I12: 1.093865 | J12: 1.49 | K12: 25 | L12: 23 | M12: 220 | N12: 326 | O12: 356.6 | P12: 19 | Q12: 307 | R12: 6.25 | S12: 0 | T12: 231 | U12: 344.19 | V12: 0 | W12: N | X12: =IF(Table2[[#This Row],[Qty available]]>Table2[[#This Row],[Qty on hand]],"Check","OK") -> OK
A13: IT-10001 | B13: Ball bearing 20-1 | C13: Bearings | D13: Clearwater Supply | E13: Main warehouse | F13: 2025-08 | G13: 1.09 | H13: 1.09 | I13: 1.09381 | J13: 1.49 | K13: 25 | M13: 0 | N13: 42 | O13: 45.94 | P13: 42 | Q13: 0 | R13: 0.81 | S13: 0 | T13: 284 | U13: 423.16 | V13: 0 | W13: N | X13: =IF(Table2[[#This Row],[Qty available]]>Table2[[#This Row],[Qty on hand]],"Check","OK") -> OK
A14: IT-10001 | B14: Ball bearing 20-1 | C14: Bearings | D14: Clearwater Supply | E14: Main warehouse | F14: 2025-09 | G14: 1.12 | H14: 1.12 | I14: 1.117529 | J14: 1.49 | K14: 25 | L14: 38 | M14: 406 | N14: 259 | O14: 289.44 | P14: 13 | Q14: 246 | R14: 4.84 | S14: 0 | T14: 189 | U14: 281.61 | V14: 0 | W14: N | X14: =IF(Table2[[#This Row],[Qty available]]>Table2[[#This Row],[Qty on hand]],"Check","OK") -> OK
A15: IT-10001 | B15: Ball bearing 20-1 | C15: Bearings | D15: Clearwater Supply | E15: Main warehouse | F15: 2025-10 | G15: 1.11 | H15: 1.11 | I15: 1.113628 | J15: 1.49 | K15: 25 | L15: 36 | M15: 280 | N15: 452 | O15: 503.36 | P15: 25 | Q15: 427 | R15: 10.61 | S15: 7 | T15: 87 | U15: 129.63 | V15: 0 | W15: N | X15: =IF(Table2[[#This Row],[Qty available]]>Table2[[#This Row],[Qty on hand]],"Check","OK") -> OK
A16: IT-10001 | B16: Ball bearing 20-1 | C16: Bearings | D16: Clearwater Supply | E16: Main warehouse | F16: 2025-11 | G16: 1.1 | H16: 1.1 | I16: 1.109823 | J16: 1.49 | K16: 25 | L16: 39 | M16: 175 | N16: 453 | O16: 502.75 | P16: 32 | Q16: 421 | R16: 13.09 | S16: 8 | T16: 174 | U16: 259.26 | V16: 0 | W16: N | X16: =IF(Table2[[#This Row],[Qty available]]>Table2[[#This Row],[Qty on hand]],"Check","OK") -> OK
A17: IT-10001 | B17: Ball bearing 20-1 | C17: Bearings | D17: Clearwater Supply | E17: Main warehouse | F17: 2025-12 | G17: 1.09 | H17: 1.09 | I17: 1.102412 | J17: 1.49 | K17: 25 | L17: 22 | M17: 270 | N17: 456 | O17: 502.7 | P17: 38 | Q17: 418 | R17: 11.35 | S17: 2 | T17: 267 | U17: 397.83 | V17: 0 | W17: N | X17: =IF(Table2[[#This Row],[Qty available]]>Table2[[#This Row],[Qty on hand]],"Check","OK") -> OK
A18: IT-10001 | B18: Ball bearing 20-1 | C18: Bearings | D18: Clearwater Supply | E18: Main warehouse | F18: 2026-01 | G18: 1.11 | H18: 1.11 | I18: 1.105992 | J18: 1.49 | K18: 25 | L18: 25 | M18: 406 | N18: 781 | O18: 863.78 | P18: 64 | Q18: 717 | R18: 19.66 | S18: 2 | T18: 81 | U18: 120.69 | V18: 0 | W18: N | X18: =IF(Table2[[#This Row],[Qty available]]>Table2[[#This Row],[Qty on hand]],"Check","OK") -> OK
A19: IT-10001 | B19: Ball bearing 20-1 | C19: Bearings | D19: Clearwater Supply | E19: Main warehouse | F19: 2026-02 | G19: 1.1 | H19: 1.1 | I19: 1.106 | J19: 1.53 | K19: 25 | M19: 0 | N19: 605 | O19: 669.13 | P19: 44 | Q19: 561 | R19: 14.84 | S19: 1 | T19: 176 | U19: 269.28 | V19: 0 | W19: N | X19: =IF(Table2[[#This Row],[Qty available]]>Table2[[#This Row],[Qty on hand]],"Check","OK") -> OK
A20: IT-10001 | B20: Ball bearing 20-1 | C20: Bearings | D20: Clearwater Supply | E20: Main warehouse | F20: 2026-03 | G20: 1.1 | H20: 1.1 | I20: 1.104441 | J20: 1.53 | K20: 25 | L20: 23 | M20: 211 | N20: 572 | O20: 631.74 | P20: 32 | Q20: 540 | R20: 14.68 | S20: 1 | T20: 244 | U20: 373.32 | V20: 0 | W20: N | X20: =IF(Table2[[#This Row],[Qty available]]>Table2[[#This Row],[Qty on hand]],"Check","OK") -> OK
A21: IT-10001 | B21: Ball bearing 20-1 | C21: Bearings | D21: Clearwater Supply | E21: Main warehouse | F21: 2026-04 | G21: 1.14 | H21: 1.14 | I21: 1.107657 | J21: 1.53 | K21: 25 | L21: 24 | M21: 57 | N21: 606 | O21: 671.24 | P21: 57 | Q21: 549 | R21: 17.39 | S21: 15 | T21: 23 | U21: 35.19 | V21: 0 | W21: N | X21: =IF(Table2[[#This Row],[Qty available]]>Table2[[#This Row],[Qty on hand]],"Check","OK") -> OK
A22: IT-10001 | B22: Ball bearing 20-1 | C22: Bearings | D22: Clearwater Supply | E22: Main warehouse | F22: 2026-05 | G22: 1.15 | H22: 1.15 | I22: 1.111412 | J22: 1.53 | K22: 25 | L22: 22 | M22: 59 | N22: 432 | O22: 480.13 | P22: 51 | Q22: 381 | R22: 11.36 | S22: 3 | T22: 233 | U22: 356.49 | V22: 0 | W22: N | X22: =IF(Table2[[#This Row],[Qty available]]>Table2[[#This Row],[Qty on hand]],"Check","OK") -> OK
A23: IT-10001 | B23: Ball bearing 20-1 | C23: Bearings | D23: Clearwater Supply | E23: Main warehouse | F23: 2026-06 | G23: 1.15 | H23: 1.15 | I23: 1.124268 | J23: 1.53 | K23: 25 | L23: 25 | M23: 216 | N23: 478 | O23: 537.4 | P23: 25 | Q23: 453 | R23: 14.59 | S23: 2 | T23: 170 | U23: 260.1 | V23: 0 | W23: N | X23: =IF(Table2[[#This Row],[Qty available]]>Table2[[#This Row],[Qty on hand]],"Check","OK") -> OK
A24: IT-10001 | B24: Ball bearing 20-1 | C24: Bearings | D24: Clearwater Supply | E24: Main warehouse | F24: 2026-07 | G24: 1.13 | H24: 1.13 | I24: 1.124258 | J24: 1.53 | K24: 25 | M24: 0 | N24: 364 | O24: 409.23 | P24: 64 | Q24: 300 | R24: 9.25 | S24: 3 | T24: 114 | U24: 174.42 | V24: 0 | W24: N | X24: =IF(Table2[[#This Row],[Qty available]]>Table2[[#This Row],[Qty on hand]],"Check","OK") -> OK
A25: IT-10001 | B25: Ball bearing 20-1 | C25: Bearings | D25: Clearwater Supply | E25: Main warehouse | F25: 2026-08 | G25: 1.13 | H25: 1.13 | I25: 1.12625 | J25: 1.53 | K25: 25 | L25: 40 | M25: 192 | N25: 280 | O25: 315.35 | P25: 57 | Q25: 223 | R25: 6.57 | S25: 2 | T25: 276 | U25: 422.28 | V25: 0 | W25: N | X25: =IF(Table2[[#This Row],[Qty available]]>Table2[[#This Row],[Qty on hand]],"Check","OK") -> OK
A26: IT-10002 | B26: Ball bearing A-2 | C26: Bearings | D26: Clearwater Supply | E26: Main warehouse | F26: 2024-09 | G26: 3.74 | H26: 4.05 | I26: 3.94 | J26: 5.58 | K26: 59 | M26: 0 | N26: 0 | O26: 0 | P26: 0 | Q26: 0 | S26: 230 | T26: 0 | U26: 0 | V26: 0 | W26: N | X26: =IF(Table2[[#This Row],[Qty available]]>Table2[[#This Row],[Qty on hand]],"Check","OK") -> OK
A27: IT-10002 | B27: Ball bearing A-2 | C27: Bearings | D27: Clearwater Supply | E27: Main warehouse | F27: 2024-10 | G27: 3.81 | H27: 4.12 | I27: 3.94 | J27: 5.58 | K27: 59 | M27: 0 | N27: 0 | O27: 0 | P27: 0 | Q27: 0 | S27: 261 | T27: 0 | U27: 0 | V27: 0 | W27: N | X27: =IF(Table2[[#This Row],[Qty available]]>Table2[[#This Row],[Qty on hand]],"Check","OK") -> OK
A28: IT-10002 | B28: Ball bearing A-2 | C28: Bearings | D28: Clearwater Supply | E28: Main warehouse | F28: 2024-11 | G28: 3.76 | H28: 4.07 | I28: 3.94 | J28: 5.58 | K28: 59 | M28: 0 | N28: 0 | O28: 0 | P28: 0 | Q28: 0 | S28: 291 | T28: 0 | U28: 0 | V28: 0 | W28: N | X28: =IF(Table2[[#This Row],[Qty available]]>Table2[[#This Row],[Qty on hand]],"Check","OK") -> OK
A29: IT-10002 | B29: Ball bearing A-2 | C29: Bearings | D29: Clearwater Supply | E29: Main warehouse | F29: 2024-12 | G29: 3.75 | H29: 4.06 | I29: 3.94 | J29: 5.58 | K29: 59 | M29: 0 | N29: 0 | O29: 0 | P29: 0 | Q29: 0 | S29: 322 | T29: 0 | U29: 0 | V29: 0 | W29: N | X29: =IF(Table2[[#This Row],[Qty available]]>Table2[[#This Row],[Qty on hand]],"Check","OK") -> OK
A30: IT-10002 | B30: Ball bearing A-2 | C30: Bearings | D30: Clearwater Supply | E30: Main warehouse | F30: 2025-01 | G30: 3.82 | H30: 4.13 | I30: 3.94 | J30: 5.58 | K30: 59 | M30: 0 | N30: 0 | O30: 0 | P30: 0 | Q30: 0 | S30: 353 | T30: 0 | U30: 0 | V30: 0 | W30: N | X30: =IF(Table2[[#This Row],[Qty available]]>Table2[[#This Row],[Qty on hand]],"Check","OK") -> OK
A31: IT-10002 | B31: Ball bearing A-2 | C31: Bearings | D31: Clearwater Supply | E31: Main warehouse | F31: 2025-02 | G31: 3.74 | H31: 4.05 | I31: 3.94 | J31: 5.74 | K31: 59 | M31: 0 | N31: 0 | O31: 0 | P31: 0 | Q31: 0 | S31: 381 | T31: 0 | U31: 0 | V31: 0 | W31: N | X31: =IF(Table2[[#This Row],[Qty available]]>Table2[[#This Row],[Qty on hand]],"Check","OK") -> OK
A32: IT-10002 | B32: Ball bearing A-2 | C32: Bearings | D32: Clearwater Supply | E32: Main warehouse | F32: 2025-03 | G32: 3.68 | H32: 3.98 | I32: 3.98 | J32: 5.74 | K32: 59 | L32: 53 | M32: 56 | N32: 56 | O32: 222.88 | P32: 0 | Q32: 56 | S32: 412 | T32: 0 | U32: 0 | V32: 0 | W32: N | X32: =IF(Table2[[#This Row],[Qty available]]>Table2[[#This Row],[Qty on hand]],"Check","OK") -> OK
A33: IT-10002 | B33: Ball bearing A-2 | C33: Bearings | D33: Clearwater Supply | E33: Main warehouse | F33: 2025-04 | G33: 3.89 | H33: 4.21 | I33: 4.140378 | J33: 5.74 | K33: 59 | L33: 51 | M33: 129 | N33: 185 | O33: 765.97 | P33: 0 | Q33: 185 | S33: 442 | T33: 0 | U33: 0 | V33: 0 | W33: N | X33: =IF(Table2[[#This Row],[Qty available]]>Table2[[#This Row],[Qty on hand]],"Check","OK") -> OK
A34: IT-10002 | B34: Ball bearing A-2 | C34: Bearings | D34: Clearwater Supply | E34: Main warehouse | F34: 2025-05 | G34: 3.79 | H34: 4.1 | I34: 4.110071 | J34: 5.74 | K34: 59 | L34: 53 | M34: 557 | N34: 567 | O34: 2330.41 | P34: 31 | Q34: 536 | R34: 42.58 | S34: 1 | T34: 175 | U34: 1004.5 | V34: 0 | W34: N | X34: =IF(Table2[[#This Row],[Qty available]]>Table2[[#This Row],[Qty on hand]],"Check","OK") -> OK
A35: IT-10002 | B35: Ball bearing A-2 | C35: Bearings | D35: Clearwater Supply | E35: Main warehouse | F35: 2025-06 | G35: 3.89 | H35: 4.21 | I35: 4.167138 | J35: 5.74 | K35: 59 | L35: 57 | M35: 755 | N35: 1153 | O35: 4804.71 | P35: 27 | Q35: 1126 | R35: 43.57 | S35: 8 | T35: 169 | U35: 970.06 | V35: 0 | W35: N | X35: =IF(Table2[[#This Row],[Qty available]]>Table2[[#This Row],[Qty on hand]],"Check","OK") -> OK
A36: IT-10002 | B36: Ball bearing A-2 | C36: Bearings | D36: Clearwater Supply | E36: Main warehouse | F36: 2025-07 | G36: 3.79 | H36: 4.1 | I36: 4.148627 | J36: 5.74 | K36: 59 | L36: 59 | M36: 439 | N36: 1209 | O36: 5015.69 | P36: 94 | Q36: 1115 | R36: 21.86 | S36: 2 | T36: 383 | U36: 2198.42 | V36: 0 | W36: N | X36: =IF(Table2[[#This Row],[Qty available]]>Table2[[#This Row],[Qty on hand]],"Check","OK") -> OK
A37: IT-10002 | B37: Ball bearing A-2 | C37: Bearings | D37: Clearwater Supply | E37: Main warehouse | F37: 2025-08 | G37: 3.87 | H37: 4.19 | I37: 4.161434 | J37: 5.74 | K37: 59 | L37: 59 | M37: 542 | N37: 1283 | O37: 5339.12 | P37: 67 | Q37: 1216 | R37: 16.53 | S37: 0 | T37: 468 | U37: 2686.32 | V37: 0 | W37: N | X37: =IF(Table2[[#This Row],[Qty available]]>Table2[[#This Row],[Qty on hand]],"Check","OK") -> OK
A38: IT-10002 | B38: Ball bearing A-2 | C38: Bearings | D38: Clearwater Supply | E38: Main warehouse | F38: 2025-09 | G38: 3.79 | H38: 4.1 | I38: 4.15027 | J38: 5.74 | K38: 59 | L38: 53 | M38: 285 | N38: 1445 | O38: 5997.14 | P38: 40 | Q38: 1405 | R38: 19.5 | S38: 4 | T38: 123 | U38: 706.02 | V38: 0 | W38: N | X38: =IF(Table2[[#This Row],[Qty available]]>Table2[[#This Row],[Qty on hand]],"Check","OK") -> OK
A39: IT-10002 | B39: Ball bearing A-2 | C39: Bearings | D39: Clearwater Supply | E39: Main warehouse | F39: 2025-10 | G39: 3.91 | H39: 4.23 | I39: 4.15027 | J39: 5.74 | K39: 59 | M39: 0 | N39: 999 | O39: 4146.12 | P39: 54 | Q39: 945 | R39: 12.66 | S39: 1 | T39: 446 | U39: 2560.04 | V39: 0 | W39: N | X39: =IF(Table2[[#This Row],[Qty available]]>Table2[[#This Row],[Qty on hand]],"Check","OK") -> OK
A40: IT-10002 | B40: Ball bearing A-2 | C40: Bearings | D40: Clearwater Supply | E40: Main warehouse | F40: 2025-11 | G40: 3.84 | H40: 4.16 | I40: 4.15027 | J40: 5.74 | K40: 59 | M40: 0 | N40: 666 | O40: 2764.08 | P40: 121 | Q40: 545 | R40: 9.6 | S40: 0 | T40: 333 | U40: 1911.42 | V40: 0 | W40: N | X40: =IF(Table2[[#This Row],[Qty available]]>Table2[[#This Row],[Qty on hand]],"Check","OK") -> OK
...

Sheet Stockout Status Distrirbution
A3: Row Labels | B3: Count of Stocked out (Y/N)
A4: N | B4: 3486
A5: Y | B5: 114
A6: Grand Total | B6: 3600

Sheet Revenue bu category
A3: Row Labels | B3: Sum of Revenue
A4: Bearings | B4: 5253716.7
A5: Electrical | B5: 4601753.6
A6: Fasteners | B6: 4548349.1
A7: Fluid power | B7: 6138005.6
A8: Power transmission | B8: 3224943.4
A9: Grand Total | B9: 23766768

Sheet Average Lead Time by Supplier
A3: Row Labels | B3: Average of Lead time actual days
A4: Clearwater Supply | B4: 37.14053
A5: Eastbrook Co | B5: 40.77027
A6: Granite Partners | B6: 38.564236
A7: Northfield Supply | B7: 33.553922
A8: Summit Trading | B8: 35.343173
A9: Grand Total | B9: 37.138155

Sheet Stock Value by Warehouse
A3: Row Labels | B3: Sum of Stock value
A4: Main warehouse | B4: 14262357
A5: North warehouse | B5: 23847966
A6: Grand Total | B6: 38110323

Sheet Lost Sales Units by Category
A3: Row Labels | B3: Sum of Lost sales units (stockout)
A4: Bearings | B4: 3501
A5: Electrical | B5: 3335
A6: Fasteners | B6: 4939
A7: Fluid power | B7: 2901
A8: Power transmission | B8: 1258
A9: Grand Total | B9: 15934

Sheet Sheet3
A3: Sum of Qty on hand | B3: Column Labels
A4: Row Labels | B4: Main warehouse | C4: North warehouse | D4: Grand Total
A5: Bearings | B5: 178259 | C5: 197933 | D5: 376192
A6: Electrical | B6: 190306 | C6: 327267 | D6: 517573
A7: Fasteners | B7: 88765 | C7: 252765 | D7: 341530
A8: Fluid power | B8: 147809 | C8: 187281 | D8: 335090
A9: Power transmission | B9: 43945 | C9: 218503 | D9: 262448
A10: Grand Total | B10: 649084 | C10: 1183749 | D10: 1832833
